[rank1]: Traceback (most recent call last):
[rank1]:   File "/home/yanPC2/experiments/pp/train_pp.py", line 80, in <module>
[rank1]:     stage = pipe.build_stage(stage_index=stage_index, device=rank)
[rank1]:   File "/home/yanPC2/miniconda3/envs/t1/lib/python3.9/site-packages/torch/distributed/pipelining/_IR.py", line 1143, in build_stage
[rank1]:     return _PipelineStage(stage_module, stage_index, pipe_info, device, group)
[rank1]:   File "/home/yanPC2/miniconda3/envs/t1/lib/python3.9/site-packages/torch/distributed/pipelining/stage.py", line 798, in __init__
[rank1]:     _PipelineStageBase.__init__(
[rank1]:   File "/home/yanPC2/miniconda3/envs/t1/lib/python3.9/site-packages/torch/distributed/pipelining/stage.py", line 138, in __init__
[rank1]:     raise RuntimeError(
[rank1]: RuntimeError: Pipeline group size 4 cannot be larger than number of stages 2
[rank1]:[W222 17:24:45.584667665 ProcessGroupNCCL.cpp:1250] Warning: WARNING: process group has NOT been destroyed before we destruct ProcessGroupNCCL. On normal program exit, the application should call destroy_process_group to ensure that any pending NCCL operations have finished in this process. In rare cases this process can exit before this point and block the progress of another member of the process group. This constraint has always been present,  but this warning has only been added since PyTorch 2.4 (function operator())
E0222 17:24:45.782152 58299 site-packages/torch/distributed/elastic/multiprocessing/api.py:869] failed (exitcode: 1) local_rank: 0 (pid: 58312) of binary: /home/yanPC2/miniconda3/envs/t1/bin/python
Traceback (most recent call last):
  File "/home/yanPC2/miniconda3/envs/t1/bin/torchrun", line 33, in <module>
    sys.exit(load_entry_point('torch==2.5.1', 'console_scripts', 'torchrun')())
  File "/home/yanPC2/miniconda3/envs/t1/lib/python3.9/site-packages/torch/distributed/elastic/multiprocessing/errors/__init__.py", line 355, in wrapper
    return f(*args, **kwargs)
  File "/home/yanPC2/miniconda3/envs/t1/lib/python3.9/site-packages/torch/distributed/run.py", line 919, in main
    run(args)
  File "/home/yanPC2/miniconda3/envs/t1/lib/python3.9/site-packages/torch/distributed/run.py", line 910, in run
    elastic_launch(
  File "/home/yanPC2/miniconda3/envs/t1/lib/python3.9/site-packages/torch/distributed/launcher/api.py", line 138, in __call__
    return launch_agent(self._config, self._entrypoint, list(args))
  File "/home/yanPC2/miniconda3/envs/t1/lib/python3.9/site-packages/torch/distributed/launcher/api.py", line 269, in launch_agent
    raise ChildFailedError(
torch.distributed.elastic.multiprocessing.errors.ChildFailedError: 
============================================================
/home/yanPC2/experiments/pp/train_pp.py FAILED
------------------------------------------------------------
Failures:
  <NO_OTHER_FAILURES>
------------------------------------------------------------
Root Cause (first observed failure):
[0]:
  time      : 2025-02-22_17:24:45
  host      : administrator-Z690-AORUS-ELITE-AX-DDR4
  rank      : 1 (local_rank: 0)
  exitcode  : 1 (pid: 58312)
  error_file: <N/A>
  traceback : To enable traceback see: https://pytorch.org/docs/stable/elastic/errors.html
============================================================
